<robot xmlns:xacro="http://www.ros.org/wiki/xacro" name="lego_robot">

  <!-- MATERIALS -->
  <material name="gray">
    <color rgba="0.5 0.5 0.5 1.0"/>
  </material>
  <material name="black">
    <color rgba="0 0 0 1.0"/>
  </material>

  <!-- BASE FOOTPRINT -->
  <link name="base_footprint"> </link>

  <!-- BASE LINK -->
  <link name="base_link">
    <visual>
      <geometry>
        <box size="0.18 0.159  0.05"/>
      </geometry>
      <material name="gray"/>
    </visual>
    <collision>
      <geometry>
        <box size="0.18 0.159 0.05"/>
      </geometry>
    </collision>
    <inertial>
      <mass value="1.0"/>
      <origin xyz="0 0 0" rpy="0 0 0"/>
      <inertia ixx="0.001" iyy="0.001" izz="0.001"
               ixy="0" ixz="0" iyz="0"/>
    </inertial>
  </link>

    <!-- JOINT base_footprint → base_link -->
  <joint name="footprint_to_base" type="fixed">
    <parent link="base_footprint"/>
    <child link="base_link"/>
    <origin xyz="0 0 0.055" rpy="0 0 0"/>
  </joint>


  <!-- LEFT WHEEL -->
  <link name="left_wheel">
    <visual>
      <origin xyz="0 0 0" rpy="1.5708 1.5708 0"/>
      <geometry>
        <cylinder radius="0.042" length="0.015"/>
      </geometry>
      <material name="black"/>
    </visual>
    <collision>
      <origin xyz="0 0 0" rpy="0 1.5708 0"/>
      <geometry>
        <cylinder radius="0.042" length="0.015"/>
      </geometry>
    </collision>
    <inertial>
      <mass value="0.1"/>
      <origin xyz="0 0 0" rpy="0 1.5708 0"/>
      <inertia ixx="0.001" iyy="0.001" izz="0.001"
               ixy="0" ixz="0" iyz="0"/>
    </inertial>
  </link>

  <!-- RIGHT WHEEL -->
  <link name="right_wheel">
    <visual>
      <origin xyz="0 0 0" rpy="1.5708 1.5708 0"/>
      <geometry>
        <cylinder radius="0.03" length="0.02"/>
      </geometry>
      <material name="black"/>
    </visual>
    <collision>
      <origin xyz="0 0 0" rpy="0 1.5708 0"/>
      <geometry>
        <cylinder radius="0.03" length="0.02"/>
      </geometry>
    </collision>
    <inertial>
      <mass value="0.1"/>
      <origin xyz="0 0 0" rpy="0 1.5708 0"/>
      <inertia ixx="0.001" iyy="0.001" izz="0.001"
               ixy="0" ixz="0" iyz="0"/>
    </inertial>
  </link>

  <!-- CASTER BALL -->
  <link name="caster_wheel">
    <visual>
      <geometry>
        <sphere radius="0.015"/>
      </geometry>
      <material name="black"/>
    </visual>
    <collision>
      <geometry>
        <sphere radius="0.015"/>
      </geometry>
    </collision>
    <inertial>
      <mass value="0.05"/>
      <origin xyz="0 0 0" rpy="0 0 0"/>
      <inertia ixx="0.0001" iyy="0.0001" izz="0.0001"
               ixy="0" ixz="0" iyz="0"/>
    </inertial>
  </link>

  <!-- LIDAR -->
  <link name="lidar_link">
    <visual>
      <geometry>
        <cylinder radius="0.025" length="0.05"/>
      </geometry>
      <material name="gray"/>
    </visual>
    <collision>
      <geometry>
        <cylinder radius="0.025" length="0.05"/>
      </geometry>
    </collision>
    <inertial>
      <mass value="0.1"/>
      <origin xyz="0 0 0" rpy="0 0 0"/>
      <inertia ixx="0.001" iyy="0.001" izz="0.001"
               ixy="0" ixz="0" iyz="0"/>
    </inertial>
  </link>

  <!-- JOINTS -->
  <joint name="left_wheel_joint" type="continuous">
    <parent link="base_link"/>
    <child link="left_wheel"/>
    <origin xyz="0 0.075 -0.025" rpy="0 0 0"/>
    <axis xyz="0 1 0"/>
  </joint>

  <joint name="right_wheel_joint" type="continuous">
    <parent link="base_link"/>
    <child link="right_wheel"/>
    <origin xyz="0 -0.075 -0.025" rpy="0 0 0"/>
    <axis xyz="0 1 0"/>
  </joint>

  <joint name="caster_joint" type="fixed">
    <parent link="base_link"/>
    <child link="caster_wheel"/>
    <origin xyz="0.08 0 -0.025" rpy="0 0 0"/>
  </joint>

  <joint name="lidar_joint" type="fixed">
    <parent link="base_link"/>
    <child link="lidar_link"/>
    <origin xyz="0 0 0.05" rpy="0 0 0"/>
  </joint>

</robot>

